Workbook

Sheet 00 How to use
B2: FaithGuard Literature Review Workbook - Member: Detection
B3: Member: M.L Ahamed | Component: Detection: Channel A learned span detector, Channel B rule checker, fused and calibrated score
B4: Review question: How can unsupported or wrong claims, especially numeric ones, be found in generated answers by checking them against source documents and tables, and how can a detector's threshold be calibrated with a guarantee?
B5: Note added 30 Oct 2026: this workbook was made with Claude (Anthropic) at the team's direction, and some cells were corrected; see 'Provenance and corrections' at the end of this sheet.
B6: Sheet | C6: What it is for | D6: Feeds
B7: 01 Search log | C7: Every search exactly as run, with date, total hits and records exported; citation-chasing lookups listed separately | D7: 04 PRISMA counts
B8: 02 Screening log | C8: One row per record with title (P1), abstract (P2) and full-text (P3) decisions, exclusion reason and notes | D8: 03, 04
B9: 03 Extraction matrix | C9: Included studies: focus, setting, method, key results, authors' stated limitations, subtopic, free full-text route | D9: 05, 06, 07
B10: 04 PRISMA counts | C10: PRISMA flow counts and exclusion reasons, all calculated by formula | D10: Report / slides
B11: 05 Gaps register | C11: Gaps stated by authors and how FaithGuard addresses each (or not) | D11: Problem statement, novelty
B12: 06 Technology comparison | C12: Alternatives, criteria and FaithGuard's provisional decision for each design choice | D12: Methodology chapter
B13: 07 Reference list | C13: Full APA 7 references for every included study | D13: Report bibliography
B15: Colour key
B16: Pale yellow cells: You type here
B17: White cells with formulas: Calculated - do not overwrite
B18: Green INCLUDED cell: the record passed all three screening passes
B20: ="Completed bounded review: "&'04 PRISMA counts'!C11&" unique records screened from "&'04 PRISMA counts'!C7&" database hits ("&'04 PRISMA counts'!C9&" exported), "&'04 PRISMA counts'!C16&" included from databases and "&'04 PRISMA counts'!C20&" by citation chasing: "&'04 PRISMA counts'!C21&" studies in total." -> Completed bounded review: 198 unique records screened from 3235 database hits (200 exported), 52 included from databases and 12 by citation chasing: 64 studies in total.
B22: Golden rule
B23: Every included study has a verified peer-reviewed venue and a legal free full-text route (publisher open access, open proceedings, or the authors' own arXiv version), and every number in sheet 03 comes from the paper itself.
B25: Eligibility criteria
B26: Include (all must hold)
B27: I1. Peer-reviewed archival publication: journal article, or paper in conference or workshop proceedings.
B28: I2. Published from 1 January 2017 onwards (search filter).
B29: I3. Written in English.
B30: I4. A legal free full text exists: publisher open access, open proceedings (ACL Anthology, PMLR, NeurIPS, AAAI) or the authors' own version (arXiv).
B31: I5. Primary study, benchmark, method or survey that meets the member's scope below.
B32: Scope (in): Methods, benchmarks and surveys that check generated or claimed text against evidence (documents, tables, knowledge): hallucination, faithfulness and factual-consistency detection; fact verification including numerical and table claims; financial QA and claim verification; XBRL numeric tagging; calibration and certified thresholds for a classifier's decision (batch setting).
B33: Scope (out, applied at P1 and P2): Mitigation-only methods with no detection evaluated (decoding, fine-tuning, retrieval tricks); white-box detectors that need the generator's internal states or token probabilities (FaithGuard's checker must audit any generator); non-text modalities; domain-specific applications outside finance; accounting studies of XBRL adoption; online and non-exchangeable calibration (reviewed by Member 3).
B35: Full-text exclusion reasons (P3)
... B62: - Other cells. Every other cell in sheets 05 and 06 is left as written on 26 Oct 2026 and records the design as planned then; where it differs from the decision log, the log holds. Since 26 Oct the benchmark's labels, the second reading of its questions and every check were made by blind Claude passes, not people (D-103).

Sheet 01 Search log
A1: 01 - Search log: Detection
A2: Every search below was run as written on the date shown. Database searches used the OpenAlex works API (filter title_and_abstract.search, publication date from 2017-01-01, sorted by citation count, first 25 records exported). DBLP's API answered with a bot check and the Semantic Scholar API with HTTP 429 (rate limit), so OpenAlex, which indexes ACL Anthology, arXiv, ACM, IEEE, Springer and other publishers, was used for all searches.
A4: # | B4: Database | C4: Search string (exactly as run) | D4: Date run | E4: Results (total hits) | F4: Records exported for screening | G4: Notes / filters applied
A6: M1-01 | B6: OpenAlex (works API) | C6: "hallucination detection" AND ("retrieval-augmented" OR RAG) | D6: 2026-10-25 | E6: 231 | F6: 25 | G6: title_and_abstract.search; from_publication_date:2017-01-01; sort cited_by_count desc; per-page 25
A7: M1-02 | B7: OpenAlex (works API) | C7: hallucination AND ("token-level" OR "span-level") AND detection | D7: 2026-10-25 | E7: 143 | F7: 25 | G7: title_and_abstract.search; from_publication_date:2017-01-01; sort cited_by_count desc; per-page 25
A8: M1-03 | B8: OpenAlex (works API) | C8: "factual consistency" AND (evaluation OR detection) AND (entailment OR NLI) | D8: 2026-10-25 | E8: 52 | F8: 25 | G8: title_and_abstract.search; from_publication_date:2017-01-01; sort cited_by_count desc; per-page 25
A9: M1-04 | B9: OpenAlex (works API) | C9: "fact verification" AND (table OR tabular) | D9: 2026-10-25 | E9: 94 | F9: 25 | G9: title_and_abstract.search; from_publication_date:2017-01-01; sort cited_by_count desc; per-page 25
A10: M1-05 | B10: OpenAlex (works API) | C10: (financial OR finance) AND ("claim verification" OR "fact-checking" OR "hallucination") | D10: 2026-10-25 | E10: 1772 | F10: 25 | G10: title_and_abstract.search; from_publication_date:2017-01-01; sort cited_by_count desc; per-page 25
A11: M1-06 | B11: OpenAlex (works API) | C11: XBRL AND ("language model" OR "natural language processing" OR tagging) | D11: 2026-10-25 | E11: 164 | F11: 25 | G11: title_and_abstract.search; from_publication_date:2017-01-01; sort cited_by_count desc; per-page 25
A12: M1-07 | B12: OpenAlex (works API) | C12: "numerical claims" AND ("fact-checking" OR verification) | D12: 2026-10-25 | E12: 411 | F12: 25 | G12: title_and_abstract.search; from_publication_date:2017-01-01; sort cited_by_count desc; per-page 25
A13: M1-08 | B13: OpenAlex (works API) | C13: ("risk control" OR "risk-controlling") AND (conformal OR "distribution-free") | D13: 2026-10-25 | E13: 368 | F13: 25 | G13: title_and_abstract.search; from_publication_date:2017-01-01; sort cited_by_count desc; per-page 25
D28: TOTAL RECORDS IDENTIFIED | E28: =SUM(E6:E26) -> 3235 | F28: =SUM(F6:F26) -> 200
A30: Citation-chasing lookups (other methods; not counted as database identification)
A31: # | B31: Database | C31: Search string (exactly as run) | D31: Date run | E31: Results (total hits) | F31: Records returned | G31: Purpose
A32: CC-01 | B32: OpenAlex (works API) | C32: SelfCheckGPT OR FActScore OR HaluEval OR MiniCheck OR SummaC OR FinQA OR FinDVer OR "Learn then Test" OR "On Calibration of Modern Neural Networks" OR "Conformal Factuality Guarantees" | D32: 2026-10-25 | E32: 102 | F32: 50 | G32: title.search; sort cited_by_count desc; per-page 50. Exact-title lookup to locate citation-chased papers and published versions
A33: CC-02 | B33: OpenAlex (works API) | C33: "Survey of Hallucination in Natural Language Generation" OR RAGTruth OR "Fine-grained Hallucination Detection and Editing" OR "Re-evaluating Factual Consistency Evaluation" OR TabFact OR FEVEROUS OR "TAT-QA" OR ConvFinQA OR "TAT-LLM" | D33: 2026-10-25 | E33: 36 | F33: 36 | G33: title.search; sort cited_by_count desc; per-page 50. Exact-title lookup to locate citation-chased papers and published versions

Sheet 02 Screening log
A1: 02 - Screening log: Detection
A2: One row per unique record. P1 = title pass, P2 = abstract pass (title and venue when no abstract was indexed), P3 = full-text pass. Type KEEP or DROP; the INCLUDED column is a formula. Database records are numbered in search order; citation-chased records follow.
A4: # | B4: Title | C4: First author | D4: Year | E4: Venue | F4: Database / index searched | G4: P1 Title | H4: P2 Abstract | I4: P3 Full text | J4: Exclusion reason (P3) | K4: INCLUDED | L4: Route | M4: Screening note | N4: OpenAlex ID | O4: DOI / link
A6: 1 | B6: A Survey on Hallucination in Large Language Models: Principles, Taxonomy, Challenges, and Open Questions | C6: Lei Huang | D6: 2025 | E6: ACM TOIS 43(2) | F6: OpenAlex: M1-01 | G6: KEEP | H6: KEEP | I6: KEEP | K6: =IF(AND(G6="KEEP",H6="KEEP",I6="KEEP"),"YES",IF(OR(G6="DROP",H6="DROP",I6="DROP"),"NO","")) -> YES | L6: Database search | N6: W4404534210 | O6: https://doi.org/10.1145/3703155
A7: 2 | B7: RAG-HAT: A Hallucination-Aware Tuning Pipeline for LLM in Retrieval-Augmented Generation | C7: Juntong Song | D7: 2024 | E7: Conference on Empirical Methods in Natural Language Processing: Industry Track (EMNLP) | F7: OpenAlex: M1-01 | G7: DROP | K7: =IF(AND(G7="KEEP",H7="KEEP",I7="KEEP"),"YES",IF(OR(G7="DROP",H7="DROP",I7="DROP"),"NO","")) -> NO | L7: Database search | M7: Mitigation or generation method; no detection evaluated (hallucination-aware fine-tuning pipeline) | N7: W4404783652 | O7: https://doi.org/10.18653/v1/2024.emnlp-industry.113
A8: 3 | B8: Citation-Enhanced Generation for LLM-based Chatbots | C8: Weitao Li | D8: 2024 | E8: Annual Meeting of the Association for Computational Linguistics (ACL) | F8: OpenAlex: M1-01 | G8: DROP | K8: =IF(AND(G8="KEEP",H8="KEEP",I8="KEEP"),"YES",IF(OR(G8="DROP",H8="DROP",I8="DROP"),"NO","")) -> NO | L8: Database search | M8: Mitigation or generation method; no detection evaluated (citation generation) | N8: W4402671914 | O8: https://doi.org/10.18653/v1/2024.acl-long.79
A9: 4 | B9: A scalable framework for evaluating multiple language models through cross-domain generation and hallucination detection | C9: Sorup Chakraborty | D9: 2025 | E9: Scientific Reports | F9: OpenAlex: M1-01 | G9: KEEP | H9: DROP | K9: =IF(AND(G9="KEEP",H9="KEEP",I9="KEEP"),"YES",IF(OR(G9="DROP",H9="DROP",I9="DROP"),"NO","")) -> NO | L9: Database search | M9: Benchmarks generator LLMs across domains; hallucination detection is only a metric, not evaluated as a method | N9: W4413269875 | O9: https://doi.org/10.1038/s41598-025-15203-5
A10: 5 | B10: AI Overview Capture Registry — Batch 1, June 2026 (EA-WG-CAPTURES-01 v1.0) | C10: Lee Sharks | D10: 2026 | E10: Zenodo | F10: OpenAlex: M1-01 | G10: DROP | K10: =IF(AND(G10="KEEP",H10="KEEP",I10="KEEP"),"YES",IF(OR(G10="DROP",H10="DROP",I10="DROP"),"NO","")) -> NO | L10: Database search | M10: Not a research study: data registry on Zenodo | N10: W7164760417 | O10: https://doi.org/10.5281/zenodo.20683855
A11: 6 | B11: Fine-grained Hallucination Detection and Editing for Language Models | C11: Abhika Mishra | D11: 2024 | E11: COLM 2024 | F11: OpenAlex: M1-01 | G11: KEEP | H11: KEEP | I11: KEEP | K11: =IF(AND(G11="KEEP",H11="KEEP",I11="KEEP"),"YES",IF(OR(G11="DROP",H11="DROP",I11="DROP"),"NO","")) -> YES | L11: Database search | N11: W4391013695 | O11: https://doi.org/10.48550/arxiv.2401.06855
A12: 7 | B12: Mitigating hallucinations in healthcare AI: a systematic review of evidence-based strategies | C12: Sanjay Basu | D12: 2026 | E12: BMC Health Services Research | F12: OpenAlex: M1-01 | G12: DROP | K12: =IF(AND(G12="KEEP",H12="KEEP",I12="KEEP"),"YES",IF(OR(G12="DROP",H12="DROP",I12="DROP"),"NO","")) -> NO | L12: Database search | M12: Domain-specific application outside finance: healthcare (mitigation review) | N12: W7163771632 | O12: https://doi.org/10.1186/s12913-026-14851-1
A13: 8 | B13: Lrp4rag: Detecting Hallucinations in Retrieval-Augmented Generation Via Layer-Wise Relevance Propagation | C13: Haichuan Hu | D13: 2025 | E13: SSRN Electronic Journal | F13: OpenAlex: M1-01 | G13: KEEP | H13: DROP | K13: =IF(AND(G13="KEEP",H13="KEEP",I13="KEEP"),"YES",IF(OR(G13="DROP",H13="DROP",I13="DROP"),"NO","")) -> NO | L13: Database search | M13: White-box: needs the generator's internal states (layer-wise relevance propagation; no abstract, decided on title) | N13: W4409352943 | O13: https://doi.org/10.2139/ssrn.5199254
A14: 9 | B14: RAGTruth: A Hallucination Corpus for Developing Trustworthy Retrieval-Augmented Language Models | C14: Cheng Niu | D14: 2024 | E14: ACL 2024 (Long Papers) | F14: OpenAlex: M1-01 | G14: KEEP | H14: KEEP | I14: KEEP | K14: =IF(AND(G14="KEEP",H14="KEEP",I14="KEEP"),"YES",IF(OR(G14="DROP",H14="DROP",I14="DROP"),"NO","")) -> YES | L14: Database search | M14: Record is the arXiv version; the peer-reviewed version was assessed | N14: W4390528749 | O14: https://doi.org/10.48550/arxiv.2401.00396
A15: 10 | B15: Chainpoll: A high efficacy method for LLM hallucination detection | C15: Friel, Robert | D15: 2023 | E15: arXiv preprint | F15: OpenAlex: M1-01 | G15: KEEP | H15: KEEP | I15: DROP | J15: Not peer-reviewed | K15: =IF(AND(G15="KEEP",H15="KEEP",I15="KEEP"),"YES",IF(OR(G15="DROP",H15="DROP",I15="DROP"),"NO","")) -> NO | L15: Database search | M15: arXiv preprint (2023); no peer-reviewed version found | N15: W4388092399 | O15: https://doi.org/10.48550/arxiv.2310.18344
A16: 11 | B16: Rowen: Adaptive Retrieval-Augmented Generation for Hallucination Mitigation in LLMs | C16: Hanxing Ding | D16: 2025 | E16: Annual International ACM SIGIR Conference on Research and Development in Information Retrieval in the Asia Pacific Region (SIGIR-AP) | F16: OpenAlex: M1-01 | G16: DROP | K16: =IF(AND(G16="KEEP",H16="KEEP",I16="KEEP"),"YES",IF(OR(G16="DROP",H16="DROP",I16="DROP"),"NO","")) -> NO | L16: Database search | M16: Mitigation or generation method; no detection evaluated (adaptive retrieval) | N16: W7108320559 | O16: https://doi.org/10.1145/3767695.3769500
A17: 12 | B17: Lynx: An Open Source Hallucination Evaluation Model | C17: Ravi, Selvan Sunitha | D17: 2024 | E17: arXiv preprint | F17: OpenAlex: M1-01 | G17: KEEP | H17: KEEP | I17: DROP | J17: Not peer-reviewed | K17: =IF(AND(G17="KEEP",H17="KEEP",I17="KEEP"),"YES",IF(OR(G17="DROP",H17="DROP",I17="DROP"),"NO","")) -> NO | L17: Database search | M17: arXiv preprint (2024); no peer-reviewed version found | N17: W4400611869 | O17: https://doi.org/10.48550/arxiv.2407.08488
A18: 13 | B18: ReDeEP: Detecting Hallucination in Retrieval-Augmented Generation via Mechanistic Interpretability | C18: Zhongxiang Sun | D18: 2024 | E18: arXiv preprint | F18: OpenAlex: M1-01 | G18: KEEP | H18: DROP | K18: =IF(AND(G18="KEEP",H18="KEEP",I18="KEEP"),"YES",IF(OR(G18="DROP",H18="DROP",I18="DROP"),"NO","")) -> NO | L18: Database search | M18: White-box: needs the generator's internal states (mechanistic interpretability) | N18: W4403574069 | O18: https://doi.org/10.48550/arxiv.2410.11414
A19: 14 | B19: ChemLit-QA: a human evaluated dataset for chemistry RAG tasks | C19: Geemi P. Wellawatte | D19: 2025 | E19: Machine Learning Science and Technology | F19: OpenAlex: M1-01 | G19: DROP | K19: =IF(AND(G19="KEEP",H19="KEEP",I19="KEEP"),"YES",IF(OR(G19="DROP",H19="DROP",I19="DROP"),"NO","")) -> NO | L19: Database search | M19: Domain-specific application outside finance: chemistry QA dataset | N19: W4408605330 | O19: https://doi.org/10.1088/2632-2153/adc2d6
A20: 15 | B20: RaDIO: Real-Time Hallucination Detection with Contextual Index Optimized Query Formulation for Dynamic Retrieval Augmented Generation | C20: Jia Zhu | D20: 2025 | E20: Proceedings of the AAAI Conference on Artificial Intelligence | F20: OpenAlex: M1-01 | G20: KEEP | H20: DROP | K20: =IF(AND(G20="KEEP",H20="KEEP",I20="KEEP"),"YES",IF(OR(G20="DROP",H20="DROP",I20="DROP"),"NO","")) -> NO | L20: Database search | M20: Detection only triggers retrieval inside the generation loop (mitigation) | N20: W4409362638 | O20: https://doi.org/10.1609/aaai.v39i24.34809
A21: 16 | B21: LLM-Based Automated Hallucination Detection in Multilingual Customer Service RAG Applications | C21: N.R. Patel | D21: 2025 | E21: IFIP advances in information and communication technology | F21: OpenAlex: M1-01 | G21: DROP | K21: =IF(AND(G21="KEEP",H21="KEEP",I21="KEEP"),"YES",IF(OR(G21="DROP",H21="DROP",I21="DROP"),"NO","")) -> NO | L21: Database search | M21: Domain-specific application outside finance: customer-service deployment | N21: W4411531956 | O21: https://doi.org/10.1007/978-3-031-96235-6_26
A22: 17 | B22: Efficient Dynamic Clustering-Based Document Compression for Retrieval-Augmented-Generation | C22: Weitao Li | D22: 2025 | E22: Conference-paper | F22: OpenAlex: M1-01 | G22: DROP | K22: =IF(AND(G22="KEEP",H22="KEEP",I22="KEEP"),"YES",IF(OR(G22="DROP",H22="DROP",I22="DROP"),"NO","")) -> NO | L22: Database search | M22: Off-topic: document compression for RAG | N22: W4416034634 | O22: https://doi.org/10.18653/v1/2025.findings-emnlp.522
A23: 18 | B23: Mitigating Hallucinations in AI | C23: Poonam C. Sharma | D23: 2026 | E23: Advances in computational intelligence and robotics book series | F23: OpenAlex: M1-01 | G23: DROP | K23: =IF(AND(G23="KEEP",H23="KEEP",I23="KEEP"),"YES",IF(OR(G23="DROP",H23="DROP",I23="DROP"),"NO","")) -> NO | L23: Database search | M23: Not a research study: book chapter on mitigation | N23: W7160539097 | O23: https://doi.org/10.4018/979-8-3373-7320-1.ch012
A24: 19 | B24: A framework for hallucination mitigation in domain-specialized large language models with application to aviation maintenance decision support | C24: Xuanting Lu | D24: 2026 | E24: Information Processing & Management | F24: OpenAlex: M1-01 | G24: DROP | K24: =IF(AND(G24="KEEP",H24="KEEP",I24="KEEP"),"YES",IF(OR(G24="DROP",H24="DROP",I24="DROP"),"NO","")) -> NO | L24: Database search | M24: Domain-specific application outside finance: aviation maintenance (mitigation) | N24: W7141989338 | O24: https://doi.org/10.1016/j.ipm.2026.104762
A25: 20 | B25: Learned Hallucination Detection in Black-Box LLMs Using Token-Level Entropy Production Rate | C25: Charles Moslonka | D25: 2026 | E25: Lecture notes in computer science | F25: OpenAlex: M1-01, M1-02 | G25: KEEP | H25: DROP | K25: =IF(AND(G25="KEEP",H25="KEEP",I25="KEEP"),"YES",IF(OR(G25="DROP",H25="DROP",I25="DROP"),"NO","")) -> NO | L25: Database search | M25: Needs the generator's token probabilities (token-level entropy; no abstract, decided on title) | N25: W7140082075 | O25: https://doi.org/10.1007/978-3-032-21289-4_8
A26: 21 | B26: Relational reasoning image captioning via multi-agent retrieval-augmented generation | C26: Aiwen Jiang | D26: 2025 | E26: Knowledge-Based Systems | F26: OpenAlex: M1-01 | G26: DROP | K26: =IF(AND(G26="KEEP",H26="KEEP",I26="KEEP"),"YES",IF(OR(G26="DROP",H26="DROP",I26="DROP"),"NO","")) -> NO | L26: Database search | M26: Non-text modality: image captioning | N26: W4417027849 | O26: https://doi.org/10.1016/j.knosys.2025.114977
A27: 22 | B27: Turk-LettuceDetect: A Hallucination Detection Model for Turkish RAG Applications | C27: Selva Taş | D27: 2025 | E27: IEEE FLLM 2025 | F27: OpenAlex: M1-01, M1-02 | G27: KEEP | H27: KEEP | I27: KEEP | K27: =IF(AND(G27="KEEP",H27="KEEP",I27="KEEP"),"YES",IF(OR(G27="DROP",H27="DROP",I27="DROP"),"NO","")) -> YES | L27: Database search | N27: W7130593875 | O27: https://doi.org/10.1109/fllm67465.2025.11390913
A28: 23 | B28: Attention Mapping for Hallucination Reduction in Arabic Financial Using Retrieval-Augmented Generation Systems | C28: Hasan A. Hasan | D28: 2025 | E28: Journal of Intelligent Informatics Networking and Cybersecurity | F28: OpenAlex: M1-01 | G28: DROP | K28: =IF(AND(G28="KEEP",H28="KEEP",I28="KEEP"),"YES",IF(OR(G28="DROP",H28="DROP",I28="DROP"),"NO","")) -> NO | L28: Database search | M28: Mitigation or generation method; no detection evaluated (attention mapping) | N28: W4416917045 | O28: https://doi.org/10.65445/3106-1192.1006
A29: 24 | B29: A Unified Framework for Mitigating Hallucinations in Large Language Models: Integrating Internal and External Validation Strategies | C29: Akshay Mittal | D29: 2025 | E29: Conference-paper | F29: OpenAlex: M1-01 | G29: DROP | K29: =IF(AND(G29="KEEP",H29="KEEP",I29="KEEP"),"YES",IF(OR(G29="DROP",H29="DROP",I29="DROP"),"NO","")) -> NO | L29: Database search | M29: Mitigation or generation method; no detection evaluated (mitigation framework) | N29: W4417003022 | O29: https://doi.org/10.1109/uemcon67449.2025.11267527
A30: 25 | B30: Hallucination Detection with Small Language Models | C30: Ming Cheung | D30: 2025 | E30: IEEE ICDE Workshops 2025 | F30: OpenAlex: M1-01 | G30: KEEP | H30: KEEP | I30: KEEP | K30: =IF(AND(G30="KEEP",H30="KEEP",I30="KEEP"),"YES",IF(OR(G30="DROP",H30="DROP",I30="DROP"),"NO","")) -> YES | L30: Database search | N30: W4413461262 | O30: https://doi.org/10.1109/icdew67478.2025.00033
A31: 26 | B31: A Token-level Reference-free Hallucination Detection Benchmark for Free-form Text Generation | C31: Tianyu Liu | D31: 2022 | E31: ACL 2022 (Long Papers) | F31: OpenAlex: M1-02 | G31: KEEP | H31: KEEP | I31: KEEP | K31: =IF(AND(G31="KEEP",H31="KEEP",I31="KEEP"),"YES",IF(OR(G31="DROP",H31="DROP",I31="DROP"),"NO","")) -> YES | L31: Database search | N31: W3155332104 | O31: https://doi.org/10.18653/v1/2022.acl-long.464
A32: 27 | B32: KCTS: Knowledge-Constrained Tree Search Decoding with Token-Level Hallucination Detection | C32: Se-Hyun Choi | D32: 2023 | E32: Conference on Empirical Methods in Natural Language Processing (EMNLP) | F32: OpenAlex: M1-02 | G32: DROP | K32: =IF(AND(G32="KEEP",H32="KEEP",I32="KEEP"),"YES",IF(OR(G32="DROP",H32="DROP",I32="DROP"),"NO","")) -> NO | L32: Database search | M32: Mitigation or generation method; no detection evaluated (decoding-time search) | N32: W4389519596 | O32: https://doi.org/10.18653/v1/2023.emnlp-main.867
A33: 28 | B33: A Token-level Reference-free Hallucination Detection Benchmark for Free-form Text Generation | C33: Tianyu Liu | D33: 2021 | E33: arXiv preprint | F33: OpenAlex: M1-02 | G33: KEEP | H33: KEEP | I33: DROP | J33: Duplicate/secondary version | K33: =IF(AND(G33="KEEP",H33="KEEP",I33="KEEP"),"YES",IF(OR(G33="DROP",H33="DROP",I33="DROP"),"NO","")) -> NO | L33: Database search | M33: arXiv version of HADES (ACL 2022, record 26) | N33: W4296300649 | O33: https://doi.org/10.48550/arxiv.2104.08704
A34: 29 | B34: Analyzing LLM Behavior in Dialogue Summarization: Unveiling Circumstantial Hallucination Trends | C34: Sanjana Ramprasad | D34: 2024 | E34: ACL 2024 (Long Papers) | F34: OpenAlex: M1-02 | G34: KEEP | H34: KEEP | I34: KEEP | K34: =IF(AND(G34="KEEP",H34="KEEP",I34="KEEP"),"YES",IF(OR(G34="DROP",H34="DROP",I34="DROP"),"NO","")) -> YES | L34: Database search | N34: W4402672049 | O34: https://doi.org/10.18653/v1/2024.acl-long.677
A35: 30 | B35: Do Androids Know They’re Only Dreaming of Electric Sheep? | C35: Sky CH-Wang | D35: 2024 | E35: Conference-paper | F35: OpenAlex: M1-02 | G35: KEEP | H35: DROP | K35: =IF(AND(G35="KEEP",H35="KEEP",I35="KEEP"),"YES",IF(OR(G35="DROP",H35="DROP",I35="DROP"),"NO","")) -> NO | L35: Database search | M35: White-box: needs the generator's internal states (probes on internal representations) | N35: W4402670439 | O35: https://doi.org/10.18653/v1/2024.findings-acl.260
A36: 31 | B36: HalLoc: Token-level Localization of Hallucinations for Vision Language Models | C36: EunKyu Park | D36: 2025 | E36: IEEE Computer Society Conference on Computer Vision and Pattern Recognition/Proceedings - IEEE Computer Society Conference on Computer Vision and Pattern Recognition/Proceedings | F36: OpenAlex: M1-02 | G36: DROP | K36: =IF(AND(G36="KEEP",H36="KEEP",I36="KEEP"),"YES",IF(OR(G36="DROP",H36="DROP",I36="DROP"),"NO","")) -> NO | L36: Database search | M36: Non-text modality: vision-language models | N36: W4413146493 | O36: https://doi.org/10.1109/cvpr52734.2025.02782
A37: 32 | B37: Quantifying Factual Divergence in Generative Models: SHAP-LIME Based Hallucination Score for LLMs | C37: Ijazul Haq | D37: 2026 | E37: Multimedia Systems | F37: OpenAlex: M1-02 | G37: KEEP | H37: KEEP | I37: DROP | J37: Free full text unavailable | K37: =IF(AND(G37="KEEP",H37="KEEP",I37="KEEP"),"YES",IF(OR(G37="DROP",H37="DROP",I37="DROP"),"NO","")) -> NO | L37: Database search | M37: Springer subscription article; no author version found on arXiv | N37: W7128010324 | O37: https://doi.org/10.1007/s00530-025-02150-4
A38: 33 | B38: Mitigating LLM Hallucination Snowballing in Multiagent Systems via Context-Aware Semantic Consistency Reasoning | C38: Xijian Xu | D38: 2026 | E38: IEEE Transactions on Neural Networks and Learning Systems | F38: OpenAlex: M1-02 | G38: DROP | K38: =IF(AND(G38="KEEP",H38="KEEP",I38="KEEP"),"YES",IF(OR(G38="DROP",H38="DROP",I38="DROP"),"NO","")) -> NO | L38: Database search | M38: Mitigation or generation method; no detection evaluated (multi-agent systems) | N38: W7125906888 | O38: https://doi.org/10.1109/tnnls.2026.3655508
A39: 34 | B39: HaluGNN: Hallucination detection in large language models using graph neural network | C39: Linggang Kong | D39: 2025 | E39: Expert Systems with Applications | F39: OpenAlex: M1-02 | G39: KEEP | H39: KEEP | I39: DROP | J39: Free full text unavailable | K39: =IF(AND(G39="KEEP",H39="KEEP",I39="KEEP"),"YES",IF(OR(G39="DROP",H39="DROP",I39="DROP"),"NO","")) -> NO | L39: Database search | M39: Elsevier subscription article; no author version found on arXiv | N39: W7117319847 | O39: https://doi.org/10.1016/j.eswa.2025.130857
A40: 35 | B40: Unsupervised Token-level Hallucination Detection from Summary Generation By-products | C40: Andreas Marfurt | D40: 2022 | E40: Conference-paper | F40: OpenAlex: M1-02 | G40: KEEP | H40: DROP | K40: =IF(AND(G40="KEEP",H40="KEEP",I40="KEEP"),"YES",IF(OR(G40="DROP",H40="DROP",I40="DROP"),"NO","")) -> NO | L40: Database search | M40: White-box: needs the generator's internal states (the summariser's own generation by-products) | N40: W4385573613 | O40: https://doi.org/10.18653/v1/2022.gem-1.21
A41: 36 | B41: Theoretical Foundations and Mitigation of Hallucination in Large Language Models | C41: Esmail Gumaan | D41: 2025 | E41: arXiv preprint | F41: OpenAlex: M1-02 | G41: DROP | K41: =IF(AND(G41="KEEP",H41="KEEP",I41="KEEP"),"YES",IF(OR(G41="DROP",H41="DROP",I41="DROP"),"NO","")) -> NO | L41: Database search | M41: Mitigation or generation method; no detection evaluated (theory and mitigation) | N41: W4414930427 | O41: https://doi.org/10.48550/arxiv.2507.22915
A42: 37 | B42: LettuceDetect: A Hallucination Detection Framework for RAG Applications | C42: Kovács, Ádám | D42: 2025 | E42: arXiv preprint | F42: OpenAlex: M1-02 | G42: KEEP | H42: KEEP | I42: DROP | J42: Not peer-reviewed | K42: =IF(AND(G42="KEEP",H42="KEEP",I42="KEEP"),"YES",IF(OR(G42="DROP",H42="DROP",I42="DROP"),"NO","")) -> NO | L42: Database search | M42: arXiv preprint (6 pages); kept as background in sheet 06 | N42: W4414848608 | O42: https://doi.org/10.48550/arxiv.2502.17125
...

Sheet 03 Extraction matrix
A1: 03 - Extraction matrix: Detection (included studies)
A2: One row per included study, ordered by subtopic. Every figure is taken from the paper itself; 'Limitations / gap' records what the authors state (or 'No limitations section' when they state none). Column O links back to the screening log.
A4: # | B4: Citation (Author, Year) | C4: Year | D4: Venue | E4: Study type | F4: Research focus | G4: Data / evaluation setting | H4: Method / model | I4: Dataset, metrics and key results | J4: Limitations / gap stated by authors | K4: Member subtopic | L4: Free full-text URL | M4: Database / index searched | N4: Free-access route | O4: Screening log #
A5: 1 | B5: Honovich et al., 2021 | C5: 2021 | D5: EMNLP 2021 (Main) | E5: Evaluation metric and dataset | F5: Reference-free factual-consistency metric for knowledge-grounded dialogue | G5: Wizard-of-Wikipedia responses annotated for factual consistency; also Topical-Chat and DialogueNLI | H5: Q2: generate questions from the response, answer them on the knowledge, compare answer spans with NLI | I5: Q2 correlates more strongly with human judgements than token-overlap and other baselines on all three datasets | J5: Authors propose mapping response parts (chit-chat, persona, factual) to their own source of truth as future work | K5: A Hallucination and faithfulness detection | L5: https://aclanthology.org/2021.emnlp-main.619.pdf | M5: OpenAlex: M1-03 | N5: ACL Anthology (open access) | O5: 50
A6: 2 | B6: Fabbri et al., 2022 | C6: 2022 | D6: NAACL-HLT 2022 (Main) | E6: Evaluation metric | F6: Whether QA-based or entailment-based metrics are better for summary consistency, under a fair comparison | G6: SummaC factual-consistency benchmark (six summarisation datasets) | H6: Systematic ablation of QA-metric components (question generation, answerability); optimised QAFactEval; combination with entailment | I6: 14% average improvement over earlier QA-based metrics on SummaC; beats the best entailment metric; QA and NLI signals are complementary | J6: Underlying models are trained on English documents only; question generation and answerability remain the key components to improve | K6: A Hallucination and faithfulness detection | L6: https://aclanthology.org/2022.naacl-main.187.pdf | M6: OpenAlex: M1-03 | N6: ACL Anthology (open access); found as arXiv record, peer-reviewed version assessed | O6: 66
A7: 3 | B7: Honovich et al., 2022 | C7: 2022 | D7: NAACL-HLT 2022 (Main) | E7: Meta-evaluation | F7: Fair, example-level comparison of factual-consistency metrics across tasks | G7: 11 datasets from summarisation, dialogue, fact verification and paraphrasing in one labelling scheme | H7: Example-level ROC AUC for 12 metrics | I7: Large NLI and QG-QA methods perform best and are complementary | J7: Headroom remains, shown by the complementarity of the best methods | K7: A Hallucination and faithfulness detection | L7: https://aclanthology.org/2022.naacl-main.287.pdf | M7: OpenAlex: M1-03 | N7: ACL Anthology (open access); found as arXiv record, peer-reviewed version assessed | O7: 55
A8: 4 | B8: Laban et al., 2022 | C8: 2022 | D8: TACL 10 | E8: Method and benchmark | F8: Making NLI models work for summary inconsistency detection | G8: SummaC benchmark: six inconsistency-detection datasets | H8: Sentence-level NLI scoring (SummaCZS) and a learned aggregation (SummaCConv) | I8: Balanced accuracy 74.4%, five points above prior work | J8: Granularity mismatch between sentence-level NLI and document-level checking is the core issue addressed | K8: A Hallucination and faithfulness detection | L8: https://arxiv.org/pdf/2111.09525 | M8: Citation chasing; located with OpenAlex title lookup CC-01 | N8: arXiv author version (pre-MIT Press TACL version) | O8: 203
A9: 5 | B9: Lotfi et al., 2022 | C9: 2022 | D9: GEM Workshop 2022 (EMNLP) | E9: Benchmark and evaluation pipeline | F9: Testing whether chatbots stay factually consistent with their persona and the conversation history | G9: ConsisTest: WH and yes/no questions built on PersonaChat; BART-family generators | H9: Hybrid evaluation pipeline that combines symbolic matching with neural (sub-symbolic) scoring | I9: Pipeline correlates well with human judgement; staying consistent with history is harder than with persona | J9: Only short, clear question-answer pairs; consistency is not only factual; the benchmark needs more and better-balanced instances | K9: A Hallucination and faithfulness detection | L9: https://aclanthology.org/2022.gem-1.47.pdf | M9: OpenAlex: M1-03 | N9: ACL Anthology (open access) | O9: 73
A10: 6 | B10: Fu et al., 2023 | C10: 2023 | D10: GEM Workshop 2023 (EMNLP) | E10: Empirical evaluation | F10: Whether LLMs can be trusted to judge the factual consistency of summaries | G10: Standard summary-factuality benchmarks with human labels; GPT-3.5, GPT-4, PaLM-2 | H10: Single-LLM QA-based factuality pipeline and direct LLM scoring, compared by correlation with humans | I10: No approach reached a correlation above 0.3 with human factuality judgements for GPT-4 or PaLM-2 (GPT-3.5 only in two error types) | J10: Closed models are continuously updated, so results may not replicate | K10: A Hallucination and faithfulness detection | L10: https://arxiv.org/pdf/2311.00681 | M10: OpenAlex: M1-03 | N10: arXiv author version of the GEM 2023 paper | O10: 64
A11: 7 | B11: Gekhman et al., 2023 | C11: 2023 | D11: EMNLP 2023 (Main) | E11: Method (synthetic training data) | F11: Training consistency checkers on LLM-labelled real model summaries | G11: 1.4M model-generated summaries labelled by a 540B LLM; TRUE benchmark and a multilingual setting | H11: TrueTeacher: generate diverse summaries, label them with an LLM, train a T5 checker | I11: ROC-AUC improves from 82.7 to 87.8 over the same model trained on prior synthetic data | J11: LLM labels are noisy; relies on a very large labelling LLM | K11: A Hallucination and faithfulness detection | L11: https://aclanthology.org/2023.emnlp-main.127.pdf | M11: OpenAlex: M1-03 | N11: ACL Anthology (open access) | O11: 52
A12: 8 | B12: Ji et al., 2023 | C12: 2023 | D12: ACM Computing Surveys 55(12) | E12: Survey | F12: Hallucination across natural language generation tasks | G12: Review covering summarisation, dialogue, QA, data-to-text, translation and more | H12: Defines intrinsic vs extrinsic hallucination; reviews causes, metrics and mitigation per task | I12: Common vocabulary and metric families (statistical, model-based) for hallucination | J12: Calls for fine-grained metrics that separate intrinsic from extrinsic errors and locate the hallucinated sub-strings | K12: A Hallucination and faithfulness detection | L12: https://arxiv.org/pdf/2202.03629 | M12: Citation chasing; located with OpenAlex title lookup CC-02 | N12: arXiv author version of the journal article | O12: 202
A13: 9 | B13: Li et al., 2023 | C13: 2023 | D13: EMNLP 2023 (Main) | E13: Benchmark | F13: How often LLMs hallucinate and whether they can recognise hallucinations | G13: Generated and human-annotated hallucinated samples for QA, dialogue, summarisation and general queries | H13: Sampling-then-filtering generation of hallucinated samples; human labelling | I13: About 19.5% of ChatGPT responses contain hallucinations; LLMs struggle to recognise them | J13: Sample quality is bounded by ChatGPT; causes of hallucination not studied | K13: A Hallucination and faithfulness detection | L13: https://aclanthology.org/2023.emnlp-main.397.pdf | M13: Citation chasing; located with OpenAlex title lookup CC-01 | N13: ACL Anthology (open access) | O13: 204
A14: 10 | B14: Manakul et al., 2023 | C14: 2023 | D14: EMNLP 2023 (Main) | E14: Method (detector) | F14: Detecting hallucinations in black-box LLM output without external resources | G14: 238 GPT-3 WikiBio passages with sentence-level factuality labels | H14: SelfCheckGPT: compare the response with stochastically sampled responses (BERTScore, QA, n-gram, NLI, prompt variants) | I14: Beats grey-box and black-box baselines at sentence and passage level; grey-box token probabilities lift NonFact AUC-PR from 72.96 (random) to 83.21 | J14: Tested on biographies of individuals; sentence-level only; prompt variant is computationally heavy | K14: A Hallucination and faithfulness detection | L14: https://aclanthology.org/2023.emnlp-main.557.pdf | M14: Citation chasing; located with OpenAlex title lookup CC-01 | N14: ACL Anthology (open access) | O14: 205
A15: 11 | B15: Min et al., 2023 | C15: 2023 | D15: EMNLP 2023 (Main) | E15: Evaluation metric | F15: Scoring long-form factual precision by atomic facts | G15: People biographies checked against Wikipedia; 6,500 generations from 13 LMs | H15: FActScore: split output into atomic facts, check each against a knowledge source; automated estimator | I15: ChatGPT reaches only 58%; the automated estimator is within 2% error of human scores | J15: Biographies and Wikipedia only; not suited to nuanced, debatable or conflicting facts | K15: A Hallucination and faithfulness detection | L15: https://aclanthology.org/2023.emnlp-main.741.pdf | M15: Citation chasing; located with OpenAlex title lookup CC-01 | N15: ACL Anthology (open access) | O15: 206
A16: 12 | B16: Wu et al., 2023 | C16: 2023 | D16: ACL 2023 (Long Papers) | E16: Method (factual-consistency checker) | F16: Training a factual-consistency checker on real model outputs instead of synthetic data | G16: TRUE benchmark (summarisation, dialogue, paraphrase, fact verification) | H16: Weak labels from several metrics aggregated by a generative labelling model, then noise-aware fine-tuning of a 435M classifier | I16: +3.3% average absolute over 11B state-of-the-art checkers on TRUE with 435M parameters; up to 30x faster | J16: Hyper-parameters need careful per-task selection; noise from the weak-labelling step carries into training (end-to-end training suggested) | K16: A Hallucination and faithfulness detection | L16: https://aclanthology.org/2023.acl-long.18.pdf | M16: OpenAlex: M1-03 | N16: ACL Anthology (open access) | O16: 62
... A68: 64 | B68: Wang et al., 2025 | C68: 2025 | D68: IEEE TNNLS 36(2) | E68: Method (statistical calibration) | F68: Controlling the loss of each individual prediction, not just its expected value | G68: Classification with a class-varying loss; weather-forecast post-processing (point-wise regression) | H68: Conformal loss-controlling prediction: extends conformal prediction from miscoverage to general losses | I68: Finite-sample loss-controlling guarantee under exchangeability, confirmed empirically | J68: How to build informationally efficient set predictors optimally is left open; relies on exchangeable data | K68: F Calibration and certified thresholds | L68: https://arxiv.org/pdf/2301.02424 | M68: OpenAlex: M1-08 | N68: arXiv author version of the journal article | O68: 188

Sheet 04 PRISMA counts
B2: 04 - PRISMA counts: Detection
B3: Every count is a formula over sheets 01 and 02, so it updates when a decision changes.
B5: Stage | C5: Count | D5: Where it comes from
B6: Identification (databases)
B7: Records identified from database searches (all hits) | C7: ='01 Search log'!E28 -> 3235 | D7: Sum of total hits, sheet 01
B8: Records not exported (beyond the 25 most-cited per search) | C8: =C7-C9 -> 3035 | D8: Hits minus exported records
B9: Records exported for screening | C9: ='01 Search log'!F28 -> 200 | D9: Sum of exported records, sheet 01
B10: Duplicate records removed (same record found by more than one search) | C10: =C9-C11 -> 2 | D10: Exported minus unique records
B11: Records screened (unique) | C11: =COUNTIF('02 Screening log'!$L$6:$L$400,"Database search") -> 198 | D11: Database rows in sheet 02
B12: Records excluded at title (P1) | C12: =COUNTIFS('02 Screening log'!$L$6:$L$400,"Database search",'02 Screening log'!$G$6:$G$400,"DROP") -> 112 | D12: P1 = DROP
B13: Records excluded at abstract (P2) | C13: =COUNTIFS('02 Screening log'!$L$6:$L$400,"Database search",'02 Screening log'!$H$6:$H$400,"DROP") -> 16 | D13: P2 = DROP
B14: Full texts assessed for eligibility | C14: =C11-C12-C13 -> 70 | D14: Screened minus P1 and P2 exclusions
B15: Full texts excluded (P3) | C15: =COUNTIFS('02 Screening log'!$L$6:$L$400,"Database search",'02 Screening log'!$I$6:$I$400,"DROP") -> 18 | D15: P3 = DROP; reasons below
B16: Studies included from databases | C16: =C14-C15 -> 52 | D16: Assessed minus excluded
B17: Identification (other methods)
B18: Records identified by citation chasing | C18: =COUNTIF('02 Screening log'!$L$6:$L$400,"Citation chasing") -> 12 | D18: Citation-chasing rows in sheet 02
B19: Full texts excluded (P3) | C19: =COUNTIFS('02 Screening log'!$L$6:$L$400,"Citation chasing",'02 Screening log'!$I$6:$I$400,"DROP") -> 0 | D19: P3 = DROP
B20: Studies included by citation chasing | C20: =C18-C19 -> 12 | D20: Identified minus excluded
B21: Total studies included | C21: =C16+C20 -> 64 | D21: Databases plus citation chasing
B22: Check: INCLUDED = YES in sheet 02 | C22: =COUNTIF('02 Screening log'!$K$6:$K$400,"YES") -> 64 | D22: Must equal the total above
B25: Full-text exclusion reasons (all routes)
B26: Reason | C26: Count | D26: Definition
B27: Not peer-reviewed | C27: =COUNTIF('02 Screening log'!$J$6:$J$400,B27) -> 7 | D27: preprints and technical reports with no archival version found, non-archival workshop papers, and journals whose peer review cannot be verified (open-access journals not listed in DOAJ).
B28: Outside date range | C28: =COUNTIF('02 Screening log'!$J$6:$J$400,B28) -> 0 | D28: published before 2017.
B29: Outside scope | C29: =COUNTIF('02 Screening log'!$J$6:$J$400,B29) -> 0 | D29: fails the member's scope at full-text stage.
B30: Free full text unavailable | C30: =COUNTIF('02 Screening log'!$J$6:$J$400,B30) -> 8 | D30: subscription-only and no author version found (arXiv searched by title).
B31: Duplicate/secondary version | C31: =COUNTIF('02 Screening log'!$J$6:$J$400,B31) -> 3 | D31: another version (e.g. arXiv copy) of a paper already in the log.
B32: Total | C32: =SUM(C27:C31) -> 18 | D32: Must equal P3 exclusions from both routes
B35: Included studies by subtopic
B36: Subtopic | C36: Count | D36: Label
B37: A | C37: =COUNTIF('03 Extraction matrix'!$K$5:$K$68,B37&"*") -> 19 | D37: Hallucination and faithfulness detection
B38: B | C38: =COUNTIF('03 Extraction matrix'!$K$5:$K$68,B38&"*") -> 6 | D38: Span- and token-level detection
B39: C | C39: =COUNTIF('03 Extraction matrix'!$K$5:$K$68,B39&"*") -> 25 | D39: Claim verification over tables and numbers
B40: D | C40: =COUNTIF('03 Extraction matrix'!$K$5:$K$68,B40&"*") -> 5 | D40: Financial QA and document verification
B41: E | C41: =COUNTIF('03 Extraction matrix'!$K$5:$K$68,B41&"*") -> 2 | D41: XBRL and financial numeric tagging
B42: F | C42: =COUNTIF('03 Extraction matrix'!$K$5:$K$68,B42&"*") -> 7 | D42: Calibration and certified thresholds

Sheet 05 Gaps register
A1: 05 - Gaps register: Detection
A2: Gaps as the authors state them (see sheet 03), and whether FaithGuard closes them. 'Not addressed' marks honest future work.
A4: # | B4: Gap as stated by the authors | C4: Source (Author, Year) | D4: Theme | E4: Your note / how it would be closed
A5: 1 | B5: Alignment-based consistency metrics give one label per claim and cannot point to the unsupported span. | C5: Zha et al., 2023a | D5: Localising errors | E5: Channel A predicts token spans with slot labels, and the repairer is told which claims were flagged.
A6: 2 | B6: Small fact-checkers reach GPT-4 level but cannot localise errors to spans. | C6: Tang et al., 2024 | D6: Localising errors | E6: Same as above: span head plus slot head.
A7: 3 | B7: Detector generality across datasets is untested; manual versus synthetic labels is an open trade-off. | C7: Niu et al., 2024 | D7: Generalisation | E7: Splits are issuer-disjoint (a company appears in one split only), so results are on unseen companies.
A8: 4 | B8: Hallucinations in the benchmark are simulated by perturbation, not produced by real generators. | C8: Liu et al., 2022 | D8: Realistic data | E8: The controlled track (planted errors) is kept separate from the benchmark of real generator answers.
A9: 5 | B9: Span labels produced by GPT-4o may be biased; QA only; hallucination types not controlled. | C9: Rykov et al., 2025 | D9: Label quality | E9: Not closed: FaithGuard's labels and the second reading of each question are blind Claude passes, not people (checked_by: claude-check; D-103, D-104), so a model's bias can enter them too. (Corrected 30 Oct 2026; see sheet 00.)
A10: 6 | B10: Fact-verification benchmarks ignore cherry-picking, where true facts are used out of context. | C10: Aly et al., 2021 | D10: Error coverage | E10: Not addressed: FaithGuard checks numbers against the filing, not selective framing. Logged as future work.
A11: 7 | B11: Real-world numerical claims remain hard: the best system reaches macro-F1 58.32. | C11: V et al., 2024 | D11: Numeric claims | E11: Channel B recomputes figures from the filing with exact Decimal arithmetic.
A12: 8 | B12: No finance-specific or fine-tuned models were evaluated on financial claim verification. | C12: Zhao et al., 2024 | D12: Domain models | E12: FaithGuard fine-tunes a compact encoder on financial answers.
A13: 9 | B13: Gold XBRL tags contain inconsistencies; classifiers could flag wrong or missing tags. | C13: Loukas et al., 2022 | D13: Source data quality | E13: XBRL facts are mined for Channel A training examples, so tag errors are reported as a threat to validity.
A14: 10 | B14: Even with retrieval and a calculator, LLMs answer only about half of numeric XBRL queries correctly. | C14: Han et al., 2024 | D14: Arithmetic | E14: Arithmetic is done by a deterministic executor, not by the language model.
A15: 11 | B15: Conformal factuality guarantees are marginal and hold only for the calibration distribution. | C15: Mohri & Hashimoto, 2024 | D15: Guarantees | E15: FaithGuard certifies with Learn-then-Test on a held-out split and claims marginal guarantees only; shift is handled by Member 3.
A16: 12 | B16: Risk control needs calibration and test data from the same distribution and bounded losses. | C16: Bates et al., 2021 | D16: Guarantees | E16: Certification uses an issuer-disjoint calibration split; the per-item loss is bounded by construction.
... A18: 14 | B18: Existing detectors miss 'circumstantial inference' errors in LLM summaries. | C18: Ramprasad et al., 2024 | D18: Error coverage | E18: Not addressed specifically: claims are labelled supported, unsupported or unverifiable against the evidence.

Sheet 06 Technology comparison
A1: 06 - Technology comparison evidence
A2: Alternatives compared for each design choice, the criteria used, and the provisional decision recorded in the FaithGuard architecture and decision log. Preprints appear here only as background; they are excluded from the review.
A4: # | B4: Research / technology area | C4: Alternatives compared | D4: Selection criteria and provisional decision | E4: Source (citation or URL)
A5: 1 | B5: Span-level detector | C5: LLM judge (GPT-4, Lynx); NLI or alignment classifier (AlignScore, MiniCheck); sampling-based (SelfCheckGPT); token-classification encoder (LettuceDetect-style, PsiloQA encoders) | D5: Need spans, low cost on a T4 and no access to the generator. Decision: token-classification encoder warm-started from LettuceDetect v2 mmBERT-base, up to 2,048 tokens, with a span head and a slot head. | E5: Niu et al., 2024; Rykov et al., 2025; Zha et al., 2023a; Tang et al., 2024; Manakul et al., 2023; LettuceDetect (arXiv 2502.17125, preprint, background only)
A6: 2 | B6: Numeric and table checking | C6: Neural table verifiers (SAT, TAPAS variants); program-based verifiers (LPA, ProgVGAT, SASP); LLM table reasoning (Chain-of-Table, Table-R1); rule-based recomputation | D6: Need exact, explainable checks of figures in filings. Decision: deterministic rule checker over the filings' own tables (Channel B) alongside the learned detector; XBRL facts are used only to build Channel A's training examples. (Corrected 30 Oct 2026; see sheet 00.) | E6: Chen et al., 2020; Yang et al., 2020; Ou & Liu, 2022; Wang et al., 2024; Thorne & Vlachos, 2017
A7: 3 | B7: Fusing the two channels and calibrating | C7: Temperature scaling; Platt scaling; isotonic regression; learned fusion | D7: Need a calibrated probability per claim from two channels. Decision: per-claim logistic-regression fusion followed by isotonic calibration. | E7: Guo et al., 2017
A8: 4 | B8: Certifying the decision threshold | C8: RCPS (upper-confidence bound); conformal risk control (expected loss); Learn-then-Test (multiple testing, any risk); conformal factuality | D8: Need a finite-sample guarantee on the error rate of sent answers. Decision: Learn-then-Test with Hoeffding-Bentkus p-values and fixed-sequence testing, alpha = 0.10, delta = 0.05. | E8: Bates et al., 2021; Angelopoulos et al., 2024; Angelopoulos et al., 2025; Mohri & Hashimoto, 2024
A9: 5 | B9: Detector training data | C9: RAGTruth (natural RAG outputs); PsiloQA (multilingual, LLM-labelled); HADES (perturbation); TrueTeacher-style LLM labels | D9: Need realistic 'right number, wrong context' errors. Decision: 34,229 training examples from the controlled track (planted errors), XBRL-mined wrong-context negatives and RAGTruth. | E9: Niu et al., 2024; Rykov et al., 2025; Liu et al., 2022; Gekhman et al., 2023
A10: 6 | B10: Financial evidence source | C10: FinQA and TAT-QA reports; FinDVer documents; XBRL facts (FiNER) | D10: Need machine-checkable evidence. Decision: the filings' own tables as evidence (US and Sri Lankan reports); XBRL facts mined only for training examples. | E10: Chen et al., 2021; Zhu et al., 2021; Zhao et al., 2024; Loukas et al., 2022
A11: 7 | B11: Background preprints (not included) | C11: LettuceDetect (arXiv 2502.17125); Lynx (arXiv 2407.08488); ChainPoll (arXiv 2310.18344) | D11: Used only as engineering references; they fail the peer-review criterion and are excluded in sheet 02. | E11: arXiv preprints

Sheet 07 Reference list
A1: 07 - Reference list: Detection (64 included studies)
A2: APA 7 style, alphabetical. Venue, volume and pages checked against Crossref or the proceedings page; free full-text link given for each.
A4: # | B4: Citation | C4: Full reference | D4: Free full-text URL
A5: 1 | B5: Aly et al., 2021 | C5: Aly, R., Guo, Z., Schlichtkrull, M., Thorne, J., Vlachos, A., Christodoulopoulos, C., Cocarascu, O., & Mittal, A. (2021). FEVEROUS: Fact extraction and VERification over unstructured and structured information. In Proceedings of the Neural Information Processing Systems Track on Datasets and Benchmarks 1 (NeurIPS 2021). | D5: https://arxiv.org/pdf/2106.05707
A6: 2 | B6: Angelopoulos et al., 2025 | C6: Angelopoulos, A. N., Bates, S., Candès, E. J., Jordan, M. I., & Lei, L. (2025). Learn then test: Calibrating predictive algorithms to achieve risk control. The Annals of Applied Statistics, 19(2), 1641-1662. https://doi.org/10.1214/24-AOAS1998 | D6: https://arxiv.org/pdf/2110.01052
A7: 3 | B7: Angelopoulos et al., 2024 | C7: Angelopoulos, A. N., Bates, S., Fisch, A., Lei, L., & Schuster, T. (2024). Conformal risk control. In International Conference on Learning Representations (ICLR 2024). | D7: https://arxiv.org/pdf/2208.02814
A8: 4 | B8: Bates et al., 2021 | C8: Bates, S., Angelopoulos, A., Lei, L., Malik, J., & Jordan, M. (2021). Distribution-free, risk-controlling prediction sets. Journal of the ACM, 68(6), 1-34. https://doi.org/10.1145/3478535 | D8: https://arxiv.org/pdf/2101.02703
A9: 5 | B9: Chen, 2023 | C9: Chen, W. (2023). Large language models are few(1)-shot table reasoners. In Findings of the Association for Computational Linguistics: EACL 2023 (pp. 1120-1130). ACL. https://doi.org/10.18653/v1/2023.findings-eacl.83 | D9: https://aclanthology.org/2023.findings-eacl.83.pdf
A10: 6 | B10: Chen et al., 2020 | C10: Chen, W., Wang, H., Chen, J., Zhang, Y., Wang, H., Li, S., Zhou, X., & Wang, W. Y. (2020). TabFact: A large-scale dataset for table-based fact verification. In International Conference on Learning Representations (ICLR 2020). | D10: https://arxiv.org/pdf/1909.02164
A11: 7 | B11: Chen et al., 2021 | C11: Chen, Z., Chen, W., Smiley, C., Shah, S., Borova, I., Langdon, D., Moussa, R., Beane, M., Huang, T.-H., Routledge, B., & Wang, W. Y. (2021). FinQA: A dataset of numerical reasoning over financial data. In Proceedings of the 2021 Conference on Empirical Methods in Natural Language Processing (pp. 3697-3711). ACL. https://doi.org/10.18653/v1/2021.emnlp-main.300 | D11: https://aclanthology.org/2021.emnlp-main.300.pdf
A12: 8 | B12: Cheung, 2025 | C12: Cheung, M. (2025). Hallucination detection with small language models. In 2025 IEEE 41st International Conference on Data Engineering Workshops (ICDEW) (pp. 230-238). IEEE. https://doi.org/10.1109/ICDEW67478.2025.00033 | D12: https://arxiv.org/pdf/2506.22486
A13: 9 | B13: Chungkham et al., 2025 | C13: Chungkham, P., V, V., Setty, V., & Anand, A. (2025). Think right, not more: Test-time scaling for numerical claim verification. In Findings of the Association for Computational Linguistics: EMNLP 2025 (pp. 24345-24363). ACL. https://doi.org/10.18653/v1/2025.findings-emnlp.1322 | D13: https://aclanthology.org/2025.findings-emnlp.1322.pdf
A14: 10 | B14: Cohen et al., 2024 | C14: Cohen, K. M., Park, S., Simeone, O., & Shamai, S. (2024). Cross-validation conformal risk control. In 2024 IEEE International Symposium on Information Theory (ISIT) (pp. 250-255). IEEE. https://doi.org/10.1109/ISIT57864.2024.10619172 | D14: https://arxiv.org/pdf/2401.11974
A15: 11 | B15: Cui et al., 2025 | C15: Cui, Z., Huang, T., Chiang, C.-E., & Du, C. (2025). Toward verifiable misinformation detection: A multi-tool LLM agent framework. In Proceedings of the 2025 International Conference on Generative Artificial Intelligence for Business (pp. 179-185). ACM. https://doi.org/10.1145/3766918.3766948 | D15: https://arxiv.org/pdf/2508.03092
A16: 12 | B16: Das et al., 2023 | C16: Das, A., Liu, H., Kovatchev, V., & Lease, M. (2023). The state of human-centered NLP technology for fact-checking. Information Processing & Management, 60(2), 103219. https://doi.org/10.1016/j.ipm.2022.103219 | D16: https://arxiv.org/pdf/2301.03056
... A68: 64 | B68: Zhu et al., 2021 | C68: Zhu, F., Lei, W., Huang, Y., Wang, C., Zhang, S., Lv, J., Feng, F., & Chua, T.-S. (2021). TAT-QA: A question answering benchmark on a hybrid of tabular and textual content in finance. In Proceedings of the 59th Annual Meeting of the ACL and the 11th IJCNLP (Volume 1: Long Papers) (pp. 3277-3287). ACL. https://doi.org/10.18653/v1/2021.acl-long.254 | D68: https://aclanthology.org/2021.acl-long.254.pdf
